Using device: cuda
Error in sys.excepthook:                      
Epoch 1 - Average Loss: 5.5373
Test set: Average loss: 5.5184, Accuracy: 0/2620 (0.00%)
Traceback (most recent call last):
  File "/usr/lib/python3.10/linecache.py", line 46, in getlines
    return updatecache(filename, module_globals)
  File "/usr/lib/python3.10/linecache.py", line 136, in updatecache
    with tokenize.open(fullname) as fp:
  File "/usr/lib/python3.10/tokenize.py", line 396, in open
    encoding, lines = detect_encoding(buffer.readline)
  File "/usr/lib/python3.10/tokenize.py", line 365, in detect_encoding
    first = read_or_stop()
  File "/usr/lib/python3.10/tokenize.py", line 323, in read_or_stop
    return readline()
KeyboardInterrupt

Original exception was:
Traceback (most recent call last):
  File "/content/Intro-to-Neural-Cognitive-Modelling-Project/lpl on audio/train_lpl_speaker_identification.py", line 201, in <module>
    main()
  File "/content/Intro-to-Neural-Cognitive-Modelling-Project/lpl on audio/train_lpl_speaker_identification.py", line 155, in main
    for data, target in train_loader:
  File "/usr/local/lib/python3.10/dist-packages/torch/utils/data/dataloader.py", line 701, in __next__
    data = self._next_data()
  File "/usr/local/lib/python3.10/dist-packages/torch/utils/data/dataloader.py", line 1448, in _next_data
    idx, data = self._get_data()
  File "/usr/local/lib/python3.10/dist-packages/torch/utils/data/dataloader.py", line 1402, in _get_data
    success, data = self._try_get_data()
  File "/usr/local/lib/python3.10/dist-packages/torch/utils/data/dataloader.py", line 1243, in _try_get_data
    data = self._data_queue.get(timeout=timeout)
  File "/usr/lib/python3.10/queue.py", line 180, in get
    self.not_empty.wait(remaining)
  File "/usr/lib/python3.10/threading.py", line 324, in wait
    gotit = waiter.acquire(True, timeout)
KeyboardInterrupt
