Using device: cuda
Traceback (most recent call last):            
Epoch 1 - Average Loss: 1.0858
Test set: Average loss: 6.0712, Accuracy: 0/2620 (0.00%)
  File "/usr/lib/python3.10/threading.py", line 324, in wait
    gotit = waiter.acquire(True, timeout)
KeyboardInterrupt

During handling of the above exception, another exception occurred:

Traceback (most recent call last):
  File "/usr/lib/python3.10/queue.py", line 180, in get
    self.not_empty.wait(remaining)
  File "/usr/lib/python3.10/threading.py", line 324, in wait
    gotit = waiter.acquire(True, timeout)
KeyboardInterrupt

During handling of the above exception, another exception occurred:

Traceback (most recent call last):
  File "/content/Intro-to-Neural-Cognitive-Modelling-Project/lpl on audio/train_lpl_speaker_identification.py", line 210, in <module>
    main()
  File "/content/Intro-to-Neural-Cognitive-Modelling-Project/lpl on audio/train_lpl_speaker_identification.py", line 155, in main
    for data, target in train_loader:
  File "/usr/local/lib/python3.10/dist-packages/torch/utils/data/dataloader.py", line 701, in __next__
    data = self._next_data()
  File "/usr/local/lib/python3.10/dist-packages/torch/utils/data/dataloader.py", line 1448, in _next_data
    idx, data = self._get_data()
  File "/usr/local/lib/python3.10/dist-packages/torch/utils/data/dataloader.py", line 1402, in _get_data
    success, data = self._try_get_data()
  File "/usr/local/lib/python3.10/dist-packages/torch/utils/data/dataloader.py", line 1243, in _try_get_data
    data = self._data_queue.get(timeout=timeout)
  File "/usr/lib/python3.10/queue.py", line 165, in get
    with self.not_empty:
  File "/usr/lib/python3.10/threading.py", line 268, in __exit__
    return self._lock.__exit__(*args)
RuntimeError: release unlocked lock
